<?xml version="1.0"?>
<robot xmlns:xacro="http://www.ros.org/wiki/xacro"  name="robot">

<material name="white">
    <color rgba="1 1 1 1"/>
</material>

<material name="orange">
    <color rgba="1 0.3 0.1 1"/>
</material>

<material name="blue">
    <color rgba="0.2 0.2 1 1"/>
</material>

<material name="black">
    <color rgba="0 0 0 1"/>
</material>

<link name="base_link">
</link>

<joint name="chassis_joint" type="fixed">
    <parent link="base_link"/>
    <child link="chassis"/>
    <origin xyz="-0.03556 0 0"/>
</joint>

<link name="chassis">
    <visual>
        <origin xyz="0.2159 0 0.02667" rpy="0 0 0"/>
        <geometry>
            <box size="0.4318 0.35814 0.05334"/>
        </geometry>
        <material name="white"/>
    </visual>
</link>

<!-- REAR LEFT WHEEL -->

<joint name="rear_left_wheel_joint" type="continuous">
    <parent link="base_link"/>
    <child link="rear_left_wheel"/>
    <origin xyz="0 0.215 0" rpy="-${pi/2} 0 0"/>
    <axis xyz="0 0 1"/>
</joint>

<link name="rear_left_wheel">
    <visual>
        <geometry>
            <cylinder length="0.05" radius="0.0762" />/>
        </geometry>
        <material name="blue"/>
    </visual>
</link>

<!-- REAR RIGHT WHEEL -->

<joint name="rear_right_wheel_joint" type="continuous">
    <parent link="base_link"/>
    <child link="rear_right_wheel"/>
    <origin xyz="0 -0.215 0" rpy="${pi/2} 0 0"/>
    <axis xyz="0 0 -1"/>
</joint>

<link name="rear_right_wheel">
    <visual>
        <geometry>
            <cylinder length="0.05" radius="0.0762" />/>
        </geometry>
        <material name="blue"/>
    </visual>
</link>

<!-- FRONT LEFT WHEEL -->

<joint name="front_left_wheel_joint" type="continuous">
    <parent link="base_link"/>
    <child link="front_left_wheel"/>
    <origin xyz="0.368 0.215 0" rpy="-${pi/2} 0 0"/>
    <axis xyz="0 0 1"/>
</joint>

<link name="front_left_wheel">
    <visual>
        <geometry>
            <cylinder length="0.05" radius="0.0762" />/>
        </geometry>
        <material name="blue"/>
    </visual>
</link>

<!-- FRONT RIGHT WHEEL -->

<joint name="front_right_wheel_joint" type="continuous">
    <parent link="base_link"/>
    <child link="front_right_wheel"/>
    <origin xyz="0.368 -0.215 0" rpy="${pi/2} 0 0"/>
    <axis xyz="0 0 -1"/>
</joint>

<link name="front_right_wheel">
    <visual>
        <geometry>
            <cylinder length="0.05" radius="0.0762" />/>
        </geometry>
        <material name="blue"/>
    </visual>
</link>

</robot>